Workbook

Sheet 재무상태표
A1: 대한항공 재무상태표 공통형 분석 | B1: 금액 (단위: 억원) | G1: 비율
A2: 계정명 | B2: 2020 | C2: 2021 | D2: 2022 | E2: 2023 | F2: 2024 | G2: 2020 | H2: 2021 | I2: 2022 | J2: 2023 | K2: 2024 | N2: 2020 | O2: 2021 | P2: 2022 | Q2: 2023 | R2: 2024
A3: 자산(*) | B3: 251900.61 | C3: 266719.03 | D3: 289977.01 | E3: 303917.76 | F3: 470120.66 | G3: 1 | H3: 1 | I3: 1 | J3: 1 | K3: 1 | M3: 부채비율 | N3: =B17/B33 -> 6.6063284 | O3: =C17/C33 -> 2.8848108 | P3: =D17/D33 -> 2.1205623 | Q3: =E17/E33 -> 2.0963965 | R3: =F17/F33 -> 3.2881732
A4: 유동자산(*) | B4: 40025.19 | C4: 66409.968 | D4: 80909.367 | E4: 85951.696 | F4: 116168.73 | G4: =B4/B3 -> 0.15889279 | H4: =C4/C3 -> 0.24898849 | I4: =D4/D3 -> 0.27901994 | J4: =E4/E3 -> 0.28281235 | K4: =F4/F3 -> 0.24710407 | M4: 유동비율 | N4: =B4/B18 -> 0.5010806 | O4: =C4/C18 -> 0.7863889 | P4: =D4/D18 -> 0.95466214 | Q4: =E4/E18 -> 0.91342121 | R4: =F4/F18 -> 0.68441292
A5: 현금및현금성자산(*) | B5: 13145.66 | C5: 11853.751 | D5: 10569.005 | E5: 6227.8738 | F5: 22156.246 | G5: =B5/B3 -> 0.052185899 | H5: =C5/C3 -> 0.04444284 | I5: =D5/D3 -> 0.036447736 | J5: =E5/E3 -> 0.020491971 | K5: =F5/F3 -> 0.047128849 | M5: 당좌비율 | N5: =(B4-B8)/B18 -> 0.43207573 | O5: =(C4-C8)/C18 -> 0.71568803 | P5: =(D4-D8)/D18 -> 0.86851952 | Q5: =(E4-E8)/E18 -> 0.82270999 | R5: =(F4-F8)/F18 -> 0.61544108
A6: 유동금융자산(*) | B6: 6470.9663 | C6: 30758.165 | D6: 49865.23 | E6: 56152.599 | F6: 46890.718 | G6: =B6/B3 -> 0.025688569 | H6: =C6/C3 -> 0.11532047 | I6: =D6/D3 -> 0.1719627 | J6: =E6/E3 -> 0.18476248 | K6: =F6/F3 -> 0.09974188 | M6: 차입금 의존도 | N6: =((B20+B27)/B3) -> 0.14576065 | O6: =((C20+C27)/C3) -> 0.07141494 | P6: =((D20+D27)/D3) -> 0.087244889 | Q6: =((E20+E27)/E3) -> 0.09921331 | R6: =((F20+F27)/F3) -> 0.092238505
A7: 매출채권및기타유동채권(*) | B7: 8058.221 | C7: 11272.13 | D7: 11426.011 | E7: 11377.966 | F7: 15896.577 | G7: =B7/B3 -> 0.031989684 | H7: =C7/C3 -> 0.042262187 | I7: =D7/D3 -> 0.039403161 | J7: =E7/E3 -> 0.037437647 | K7: =F7/F3 -> 0.033813823 | M7: 순차입금 | N7: =(B20+B27)-B5 -> 23571.537 | O7: =(C20+C27)-C5 -> 7193.9725 | P7: =(D20+D27)-D5 -> 14730.007 | Q7: =(E20+E27)-E5 -> 23924.813 | R7: =(F20+F27)-F5 -> 21206.981
A8: 재고자산(*) | B8: 5511.9538 | C8: 5970.6364 | D8: 7300.745 | E8: 8535.8031 | F8: 11706.926 | G8: =B8/B3 -> 0.021881462 | H8: =C8/C3 -> 0.022385491 | I8: =D8/D3 -> 0.025176979 | J8: =E8/E3 -> 0.028085898 | K8: =F8/F3 -> 0.02490196
A9: 기타유동자산(*) | B9: 6838 | C9: 6555 | D9: 1748 | E9: 3657 | F9: 19518 | G9: =B9/B3 -> 0.027145627 | H9: =C9/C3 -> 0.024576424 | I9: =D9/D3 -> 0.0060280641 | J9: =E9/E3 -> 0.01203286 | K9: =F9/F3 -> 0.041517001
A10: 비유동자산(*) | B10: 211875.42 | C10: 200309.06 | D10: 209067.64 | E10: 217966.06 | F10: 353951.93 | G10: =B10/B3 -> 0.84110721 | H10: =C10/C3 -> 0.75101151 | I10: =D10/D3 -> 0.72098006 | J10: =E10/E3 -> 0.71718765 | K10: =F10/F3 -> 0.75289593
A11: 기타비유동자산(*) | B11: 6850.7951 | C11: 10127.43 | D11: 11278.324 | E11: 9651.1415 | F11: 5401.6574 | G11: =B11/B3 -> 0.027196421 | H11: =C11/C3 -> 0.037970408 | I11: =D11/D3 -> 0.038893855 | J11: =E11/E3 -> 0.031755767 | K11: =F11/F3 -> 0.011489938
A12: 투자부동산(*) | B12: 2565.7746 | C12: 2625.0993 | D12: 2687.3101 | E12: 2607.491 | F12: 2778.6307 | G12: =B12/B3 -> 0.010185662 | H12: =C12/C3 -> 0.0098421899 | I12: =D12/D3 -> 0.0092673212 | J12: =E12/E3 -> 0.0085795941 | K12: =F12/F3 -> 0.0059104629
A13: 유형자산(*) | B13: 184821.4 | C13: 169140.84 | D13: 170790.86 | E13: 181748.87 | F13: 283744.91 | G13: =B13/B3 -> 0.73370762 | H13: =C13/C3 -> 0.63415363 | I13: =D13/D3 -> 0.58898071 | J13: =E13/E3 -> 0.5980199 | K13: =F13/F3 -> 0.60355763
A14: 무형자산(*) | B14: 2681.4515 | C14: 2759.8427 | D14: 8737.5452 | E14: 8241.8568 | F14: 30774.07 | G14: =B14/B3 -> 0.010644879 | H14: =C14/C3 -> 0.010347378 | I14: =D14/D3 -> 0.030131855 | J14: =E14/E3 -> 0.027118707 | K14: =F14/F3 -> 0.065459939
A15: 기타비유동자산(*) | B15: 14892 | C15: 15594 | D15: 15574 | E15: 15717 | F15: 29707 | G15: =B15/B3 -> 0.059118555 | H15: =C15/C3 -> 0.058466019 | I15: =D15/D3 -> 0.053707706 | J15: =E15/E3 -> 0.051714648 | K15: =F15/F3 -> 0.063190161
A17: 부채(*) | B17: 218783.37 | C17: 198062.14 | D17: 197052.41 | E17: 205765.68 | F17: 360488.74 | G17: =B17/B40 -> 0.86853052 | H17: =C17/C40 -> 0.7425872 | I17: =D17/D40 -> 0.67954493 | J17: =E17/E40 -> 0.67704394 | K17: =F17/F40 -> 0.76680047
A18: 유동부채(*) | B18: 79877.748 | C18: 84449.27 | D18: 84751.834 | E18: 94098.643 | F18: 169734.86 | G18: =B18/$B$40 -> 0.31710025 | H18: =C18/$C$40 -> 0.31662259 | I18: =D18/$D$40 -> 0.29227087 | J18: =E18/$E$40 -> 0.30961877 | K18: =F18/$F$40 -> 0.36104531
A19: 매입채무및기타유동채무(*) | B19: 8327.9186 | C19: 9490.7954 | D19: 13933.227 | E19: 18141.135 | F19: 34646.713 | G19: =B19/$B$40 -> 0.033060335 | H19: =C19/$C$40 -> 0.035583495 | I19: =D19/$D$40 -> 0.048049421 | J19: =E19/$E$40 -> 0.059690935 | K19: =F19/$F$40 -> 0.07369749
A20: 단기차입금(*) | B20: 19008.87 | C20: 9855.6823 | D20: 9060.511 | E20: 10214.077 | F20: 25170.217 | G20: =B20/$B$40 -> 0.075461785 | H20: =C20/$C$40 -> 0.036951552 | I20: =D20/$D$40 -> 0.031245618 | J20: =E20/$E$40 -> 0.033608029 | K20: =F20/$F$40 -> 0.053539909
A21: 당기법인세부채(미지급법인세) | B21: 939.46501 | C21: 2302.6003 | D21: 7471.0451 | E21: 2014.3157 | F21: 2754.4845 | G21: =B21/$B$40 -> 0.0037295067 | H21: =C21/$C$40 -> 0.0086330557 | I21: =D21/$D$40 -> 0.025764267 | J21: =E21/$E$40 -> 0.0066278314 | K21: =F21/$F$40 -> 0.0058591012
A22: 유동성장기부채(*) | B22: 39472.611 | C22: 43719.551 | D22: 27502.288 | E22: 27179.636 | F22: 47234.992 | G22: =B22/$B$40 -> 0.15669915 | H22: =C22/$C$40 -> 0.16391613 | I22: =D22/$D$40 -> 0.094842995 | J22: =E22/$E$40 -> 0.089430892 | K22: =F22/$F$40 -> 0.10047419
A23: 기타단기충당부채(*) | B23: 548.64936 | C23: 1317.9707 | D23: 2830.8501 | E23: 1610.9616 | F23: 6529.2699 | G23: =B23/$B$40 -> 0.002178039 | H23: =C23/$C$40 -> 0.0049414197 | I23: =D23/$D$40 -> 0.009762326 | J23: =E23/$E$40 -> 0.0053006496 | K23: =F23/$F$40 -> 0.013888498
A24: 기타유동부채(*) | B24: 11035 | C24: 17276 | D24: 23954 | E24: 34939 | F24: 49241 | G24: =B24/$B$40 -> 0.04380696 | H24: =C24/$C$40 -> 0.064772281 | I24: =D24/$D$40 -> 0.082606549 | J24: =E24/$E$40 -> 0.11496202 | K24: =F24/$F$40 -> 0.1047412
A25: 비유동부채(*) | B25: 138905.62 | C25: 113612.87 | D25: 112300.57 | E25: 111667.03 | F25: 190753.88 | G25: =B25/$B$40 -> 0.55143027 | H25: =C25/$C$40 -> 0.42596462 | I25: =D25/$D$40 -> 0.38727406 | J25: =E25/$E$40 -> 0.36742517 | K25: =F25/$F$40 -> 0.40575516
A26: 사채(*) | B26: 12444.14 | C26: 10582.314 | D26: 18305.285 | E26: 18428.367 | F26: 14631.076 | G26: =B26/$B$40 -> 0.04940099 | H26: =C26/$C$40 -> 0.039675885 | I26: =D26/$D$40 -> 0.063126676 | J26: =E26/$E$40 -> 0.060636031 | K26: =F26/$F$40 -> 0.03112196
A27: 장기차입금(*) | B27: 17708.328 | C27: 9192.0414 | D27: 16238.501 | E27: 19938.61 | F27: 18193.009 | G27: =B27/$B$40 -> 0.070298867 | H27: =C27/$C$40 -> 0.034463388 | I27: =D27/$D$40 -> 0.055999271 | J27: =E27/$E$40 -> 0.065605281 | K27: =F27/$F$40 -> 0.038698595
A28: 이연법인세부채 | B28: 228.1309 | C28: 266.01387 | D28: 955.63386 | E28: 875.3792 | F28: 1879.4776 | G28: =B28/$B$40 -> 0.00090563855 | H28: =C28/$C$40 -> 0.00099735616 | I28: =D28/$D$40 -> 0.0032955504 | J28: =E28/$E$40 -> 0.002880316 | K28: =F28/$F$40 -> 0.0039978622
A29: 비유동금융부채(*) | B29: 67892.911 | C29: 51735.606 | D29: 40289.398 | E29: 33799.299 | F29: 89100.986 | G29: =B29/$B$40 -> 0.26952261 | H29: =C29/$C$40 -> 0.19397043 | I29: =D29/$D$40 -> 0.13893997 | J29: =E29/$E$40 -> 0.11121199 | K29: =F29/$F$40 -> 0.18952791
... A39: 비지배주주지분 | B39: 1052.2358 | C39: 1117.8541 | D39: 2982.6954 | E39: 2892.0915 | F39: 4903.0958 | G39: =B39/$B$40 -> 0.0041771864 | H39: =C39/$C$40 -> 0.0041911297 | I39: =D39/$D$40 -> 0.010285972 | J39: =E39/$E$40 -> 0.0095160333 | K39: =F39/$F$40 -> 0.010429441
A40: 부채와자본총계(*) | B40: =B33+B17 -> 251900.61 | C40: =C33+C17 -> 266719.03 | D40: =D33+D17 -> 289977.01 | E40: =E33+E17 -> 303917.76 | F40: =F33+F17 -> 470120.66 | G40: 1 | H40: 1 | I40: 1 | J40: 1 | K40: 1

Sheet 손익계산서
A1: 대한항공 손익계산서 공통형 분석 | B1: 금액 (단위: 억원) (단위가 원인 경우는 따로 표기)
A2: 계정명 | B2: 2020 | C2: 2021 | D2: 2022 | E2: 2023 | F2: 2024 | H2: 계정명 | I2: 2020 | J2: 2021 | K2: 2022 | L2: 2023 | M2: 2024
A3: 매출액(수익)(*) | B3: 76105.309 | C3: 90168.246 | D3: 140960.95 | E3: 161117.96 | F3: 178707.18 | H3: 매출액 | I3: =B3/B3 -> 1 | J3: =C3/C3 -> 1 | K3: =D3/D3 -> 1 | L3: =E3/E3 -> 1 | M3: =F3/F3 -> 1
A4: 용역수익 | B4: 75223.15 | C4: 89297.287 | D4: 140196.18 | E4: 160303.01 | F4: 177676.58 | H4: 매출원가 | I4: =B6/B3 -> 0.9000823 | J4: =C6/C3 -> 0.7665722 | K4: =D6/D3 -> 0.72682829 | L4: =E6/E3 -> 0.79757103 | M4: =F6/F3 -> 0.78970245
A5: 임대수익 | B5: 882.15871 | C5: 870.9592 | D5: 764.76851 | E5: 814.95 | F5: 1030.6 | H5: 매출총이익 | I5: =B7/B3 -> 0.099917696 | J5: =C7/C3 -> 0.2334278 | K5: =D7/D3 -> 0.27317171 | L5: =E7/E3 -> 0.20242897 | M5: =F7/F3 -> 0.21029755
A6: 매출원가(*) | B6: 68501.042 | C6: 69120.471 | D6: 102454.4 | E6: 128503.02 | F6: 141125.5 | H6: 판매비와관리비 | I6: =B8/B3 -> 0.085815653 | J6: =C8/C3 -> 0.076169713 | K6: =D8/D3 -> 0.072365265 | L6: =E8/E3 -> 0.091324706 | M6: =F8/F3 -> 0.092216119
A7: 매출총이익(손실) | B7: 7604.2671 | C7: 21047.776 | D7: 38506.544 | E7: 32614.942 | F7: 37581.684 | H7: 영업이익 | I7: =B15/B3 -> 0.014102043 | J7: =C15/C3 -> 0.15725809 | K7: =D15/D3 -> 0.20080645 | L7: =E15/E3 -> 0.11110426 | M7: =F15/F3 -> 0.11808143
A8: 판매비와관리비(*) | B8: 6531.0268 | C8: 6868.0894 | D8: 10200.676 | E8: 14714.05 | F8: 16479.683 | H8: 금융수익 | I8: =B16/B3 -> 0.011060423 | J8: =C16/C3 -> 0.040073301 | K8: =D16/D3 -> 0.027179426 | L8: =E16/E3 -> 0.027210954 | M8: =F16/F3 -> 0.036279652
A9: 인건비(*) | B9: 3131.8129 | C9: 3121.718 | D9: 3904.7804 | E9: 4669.69 | F9: 5443.99 | H9: 금융원가 | I9: =B19/B3 -> 0.098814379 | J9: =C19/C3 -> 0.048576122 | K9: =D19/D3 -> 0.030725338 | L9: =E19/E3 -> 0.036659892 | M9: =F19/F3 -> 0.033395462
A10: 유무형자산상각비(*) | B10: 853.89976 | C10: 751.28988 | D10: 902.95903 | E10: 995.24 | F10: 881.04 | H10: 기타수익 | I10: =B22/B3 -> 0.11907267 | J10: =C22/C3 -> 0.063989237 | K10: =D22/D3 -> 0.068773404 | L10: =E22/E3 -> 0.035503206 | M10: =F22/F3 -> 0.051212097
A11: 광고선전비 | B11: 154.43241 | C11: 172.87576 | D11: 364.13336 | E11: 309.47 | F11: 572.22 | H11: 기타비용 | I11: =B23/B3 -> 0.16849022 | J11: =C23/C3 -> 0.11924375 | K11: =D23/D3 -> 0.084257379 | L11: =E23/E3 -> 0.039362464 | M11: =F23/F3 -> 0.069432015
A12: 판매비(*) | B12: 557.69475 | C12: 376.67222 | D12: 912.37897 | E12: 2007.1 | F12: 2011.68 | H12: 법인세비용차감전이익 | I12: =B29/B3 -> -0.12294768 | J12: =C29/C3 -> 0.093504538 | K12: =D29/D3 -> 0.18176204 | L12: =E29/E3 -> 0.097797313 | M12: =F29/F3 -> 0.10274772
A13: 관리비(*) | B13: 1280.3738 | C13: 1916.2938 | D13: 3358.7565 | E13: 4985.59 | F13: 6031.23 | H13: 계속영업이익 | I13: =B31/B3 -> -0.10819967 | J13: =C31/C3 -> 0.064189119 | K13: =D31/D3 -> 0.12269376 | L13: =E31/E3 -> 0.070079445 | M13: =F31/F3 -> 0.077325267
A14: 기타 | B14: 552.81318 | C14: 529.23972 | D14: 757.66809 | E14: 1746.9604 | F14: 1539.5231 | H14: 당기순이익 | I14: =B33/B3 -> -0.03022373 | J14: =C33/C3 -> 0.064189119 | K14: =D33/D3 -> 0.12269376 | L14: =E33/E3 -> 0.070079445 | M14: =F33/F3 -> 0.077325267
A15: 영업이익(손실) | B15: 1073.2404 | C15: 14179.686 | D15: 28305.868 | E15: 17900.892 | F15: 21102.001
A16: 금융수익(*) | B16: 841.75688 | C16: 3613.3393 | D16: 3831.2377 | E16: 4384.1734 | F16: 6483.4344
A17: 이자수익 | B17: 424.44881 | C17: 701.29775 | D17: 1561.2177 | E17: 3018.9134 | F17: 2813.79
A18: 기타 | B18: 417 | C18: 2912 | D18: 2270 | E18: 1365 | F18: 3670
A19: 금융원가(*) | B19: 7520.2989 | C19: 4380.0237 | D19: 4331.0727 | E19: 5906.5671 | F19: 5968.009
A20: 이자비용 | B20: 5138.6253 | C20: 3909.3369 | D20: 4009.4999 | E20: 5314.1471 | F20: 5141.589
A21: 파생상품손실(*) | B21: 2381.6736 | C21: 470.68688 | D21: 321.5728 | E21: 592.42 | F21: 826.42
A22: 기타수익(*) | B22: 9062.0621 | C22: 5769.7973 | D22: 9694.3642 | E22: 5720.2041 | F22: 9151.9698
A23: 기타비용(*) | B23: 12823 | C23: 10752 | D23: 11877 | E23: 6342 | F23: 12408
A24: 외환손실(*) | B24: 5226.2392 | C24: 7597.9532 | D24: 9846.3097 | E24: 5416.0387 | F24: 11162.92
A25: 자산처분(폐기)손실(*) | B25: 602.70913 | C25: 89.12596 | D25: 251.44136 | E25: 414.64 | F25: 356.5
A26: 자산손상차손(*) | B26: 6396.8637 | C26: 2754.4154 | D26: 165.65353 | E26: 104.41 | F26: 0
... A50: *기타비용 | B50: 35090.145 | C50: 38407.319 | D50: 70029.791 | E50: 89222.2 | F50: 98289.53

Sheet 현금흐름표
A1: 대한항공 현금흐름표 공통형 분석 | B1: 금액 (단위: 억원)
A2: 계정명 | B2: 2020 | C2: 2021 | D2: 2022 | E2: 2023 | F2: 2024 | H2: 계정명 | I2: 2020 | J2: 2021 | K2: 2022 | L2: 2023 | M2: 2024
A3: 영업활동으로인한현금흐름(간접법)(*) | B3: 13767 | C3: 35142 | D3: 55724 | E3: 40925 | F3: 45589 | H3: 영업활동 현금흐름 | I3: =B3/B3 -> 1 | J3: =C3/C3 -> 1 | K3: =D3/D3 -> 1 | L3: =E3/E3 -> 1 | M3: =F3/F3 -> 1
A4: 당기순손익 | B4: -2300 | C4: 5788 | D4: 17295 | E4: 11291 | F4: 13819 | H4: 투자활동 현금흐름 | I4: =B55/B3 -> -0.0019612116 | J4: =C55/C3 -> -0.69569176 | K4: =D55/D3 -> -0.53404278 | L4: =E55/E3 -> -0.58885767 | M4: =F55/F3 -> -0.19098905
A5: 현금유출이없는비용등가산(*) | B5: 40603 | C5: 35606 | D5: 39372 | E5: 32574 | F5: 40460 | H5: 재무활동 현금흐름 | I5: =B77/B3 -> -0.6233021 | J5: =C77/C3 -> -0.34465881 | K5: =D77/D3 -> -0.48417199 | L5: =E77/E3 -> -0.50951741 | M5: =F77/F3 -> -0.47434688
A6: 퇴직급여 | B6: 1992 | C6: 1860 | D6: 2011 | E6: 2202 | F6: 2583 | H6: 당기순손익 | I6: =B4/B3 -> -0.16706617 | J6: =C4/C3 -> 0.1647032 | K6: =D4/D3 -> 0.31036896 | L6: =E4/E3 -> 0.27589493 | M6: =F4/F3 -> 0.30312137
A7: 대손상각비(대손충당금전입액) | B7: 22 | C7: -1 | D7: 3 | E7: 4 | F7: 4 | H7: 감가상각비 | I7: =B8/B3 -> 1.4077867 | J7: =C8/C3 -> 0.47322292 | K7: =D8/D3 -> 0.28817027 | L7: =E8/E3 -> 0.4070617 | M7: =F8/F3 -> 0.38105683
A8: 감가상각비 | B8: 19381 | C8: 16630 | D8: 16058 | E8: 16659 | F8: 17372 | H8: 이자비용 | I8: =B13/B3 -> 0.37328394 | J8: =C13/C3 -> 0.11123442 | K8: =D13/D3 -> 0.071943866 | L8: =E13/E3 -> 0.12984728 | M8: =F13/F3 -> 0.11279037
A9: 무형자산상각비(*) | B9: 311 | C9: 324 | D9: 440 | E9: 570 | F9: 588 | H9: 이자수익 | I9: =B25/B3 -> 0.030798286 | J9: =C25/C3 -> 0.019947641 | K9: =D25/D3 -> 0.028013064 | L9: =E25/E3 -> 0.07376909 | M9: =F25/F3 -> 0.061725416
A10: 충당부채전입액 | B10: 188 | C10: 384 | D10: 206 | E10: 260 | F10: 140 | H10: 법인세 납부 | I10: =B54/B3 -> -0.0036318733 | J10: =C54/C3 -> -0.0041830289 | K10: =D54/D3 -> -0.068318857 | L10: =E54/E3 -> -0.23156995 | M10: =F54/F3 -> -0.081510891
A11: 외환손실(*) | B11: 2167 | C11: 6092 | D11: 5838 | E11: 1985 | F11: 8230 | H11: 현금의변화 | I11: =B3+B55+B77 -> 5159 | J11: =C3+C55+C77 -> -1418 | K11: =D3+D55+D77 -> -1015 | L11: =E3+E55+E77 -> -4026 | M11: =F3+F55+F77 -> 15257
A12: 기타의대손상각비(대손충당금전입액) | B12: 6 | C12: 79 | D12: 14 | E12: 9 | F12: 205
A13: 이자비용(*) | B13: 5139 | C13: 3909 | D13: 4009 | E13: 5314 | F13: 5142
A14: 금융자산처분손실(*) | B14: 0 | C14: 0 | D14: 0 | E14: 182 | F14: 0
A15: 금융자산평가손실(*) | B15: 0 | C15: 0 | D15: 1216 | E15: 0 | F15: 0
A16: 파생상품손실(*) | B16: 2382 | C16: 471 | D16: 322 | E16: 592 | F16: 826
A17: 자산처분(폐기)손실(*) | B17: 650 | C17: 29 | D17: 242 | E17: 208 | F17: 356
A18: 자산손상차손(*) | B18: 6398 | C18: 2771 | D18: 210 | E18: -15 | F18: 23
A19: 지분법관련손실(*) | B19: 9 | C19: 0 | D19: 0 | E19: 0 | F19: 0
A20: 법인세비용 | B20: 1109 | C20: 2643 | D20: 8326 | E20: 4466 | F20: 4543
A21: 기타비용(*) | B21: 851 | C21: 416 | D21: 476 | E21: 137 | F21: 448
A22: (현금유입이없는수익등차감)(*) | B22: 15607 | C22: 7303 | D22: 8628 | E22: 6053 | F22: 12564
A23: 외환이익(*) | B23: 6102 | C23: 1829 | D23: 2740 | E23: 1096 | F23: 3673
... A95: 배당금지급(-) | B95: -610 | C95: -182 | D95: -46 | E95: -2821 | F95: -2782

Sheet 재무비율분석
A1: 대한항공 | C1: 2020 | D1: 2021 | E1: 2022 | F1: 2023 | G1: 2024
A2: 수익성 | B2: 순이익률 | C2: =손익계산서!B$33/손익계산서!B$3 -> -0.03022373 | D2: =손익계산서!C$33/손익계산서!C$3 -> 0.064189119 | E2: =손익계산서!D$33/손익계산서!D$3 -> 0.12269376 | F2: =손익계산서!E$33/손익계산서!E$3 -> 0.070079445 | G2: =손익계산서!F$33/손익계산서!F$3 -> 0.077325267
B3: ROA | C3: =손익계산서!B$33/재무상태표!B$3 -> -0.009131325 | D3: =손익계산서!C$33/재무상태표!C$3 -> 0.021700065 | E3: =손익계산서!D$33/재무상태표!D$3 -> 0.059642758 | F3: =손익계산서!E$33/재무상태표!E$3 -> 0.037151687 | G3: =손익계산서!F$33/재무상태표!F$3 -> 0.02939369
B4: ROE | C4: =손익계산서!B$33/재무상태표!B$33 -> -0.069455857 | D4: =손익계산서!C$33/재무상태표!C$33 -> 0.084300646 | E4: =손익계산서!D$33/재무상태표!D$33 -> 0.18611894 | F4: =손익계산서!E$33/재무상태표!E$33 -> 0.11503635 | G4: =손익계산서!F$33/재무상태표!F$33 -> 0.12604523
B5: EBITDA 이익률 | C5: =(손익계산서!B$29+손익계산서!B$10)/손익계산서!B$3 -> -0.11172771 | D5: =(손익계산서!C$29+손익계산서!C$10)/손익계산서!C$3 -> 0.10183663 | E5: =(손익계산서!D$29+손익계산서!D$10)/손익계산서!D$3 -> 0.18816778 | F5: =(손익계산서!E$29+손익계산서!E$10)/손익계산서!E$3 -> 0.1039744 | G5: =(손익계산서!F$29+손익계산서!F$10)/손익계산서!F$3 -> 0.1076778
A6: 효율성 | B6: 총자산회전율 | C6: =손익계산서!B$3/재무상태표!B$3 -> 0.30212435 | D6: =손익계산서!C$3/재무상태표!C$3 -> 0.33806454 | E6: =손익계산서!D$3/재무상태표!D$3 -> 0.48611077 | F6: =손익계산서!E$3/재무상태표!E$3 -> 0.53013671 | G6: =손익계산서!F$3/재무상태표!F$3 -> 0.38013047
B7: 순운전자본회전율 | C7: =손익계산서!B$3/(재무상태표!B$4-재무상태표!B$18) -> -1.9096719 | D7: =손익계산서!C$3/(재무상태표!C$4-재무상태표!C$18) -> -4.9984333 | E7: =손익계산서!D$3/(재무상태표!D$4-재무상태표!D$18) -> -36.685015 | F7: =손익계산서!E$3/(재무상태표!E$4-재무상태표!E$18) -> -19.776484 | G7: =손익계산서!F$3/(재무상태표!F$4-재무상태표!F$18) -> -3.3361975 | I7: 월별주가 | J7: 1 | K7: 2 | L7: 3 | M7: 4 | N7: 5 | O7: 6 | P7: 7 | Q7: 8 | R7: 9 | S7: 10 | T7: 11 | U7: 12
B8: 재고자산회전율 | C8: =손익계산서!B$6/재무상태표!B$8 -> 12.427724 | D8: =손익계산서!C$6/재무상태표!C$8 -> 11.576734 | E8: =손익계산서!D$6/재무상태표!D$8 -> 14.033418 | F8: =손익계산서!E$6/재무상태표!E$8 -> 15.05459 | G8: =손익계산서!F$6/재무상태표!F$8 -> 12.054872 | I8: 2020 | J8: 15164 | K8: 14299 | L8: 11990 | M8: 12696 | N8: 13273 | O8: 13453 | P8: 13492 | Q8: 13686 | R8: 14616 | S8: 15469 | T8: 19773 | U8: 21091
B9: 재고자산회전일수 | C9: =365/C8 -> 29.369818 | D9: =365/D8 -> 31.528754 | E9: =365/E8 -> 26.009345 | F9: =365/F8 -> 24.245097 | G9: =365/G8 -> 30.278213 | I9: 2021 | J9: 28700 | K9: 28150 | L9: 27200 | M9: 26900 | N9: 31950 | O9: 31500 | P9: 29900 | Q9: 31300 | R9: 33700 | S9: 30450 | T9: 26500 | U9: 29350
B10: 매출채권회전율 | C10: =손익계산서!B$3/재무상태표!B$7 -> 9.4444307 | D10: =손익계산서!C$3/재무상태표!C$7 -> 7.9992202 | E10: =손익계산서!D$3/재무상태표!D$7 -> 12.336847 | F10: =손익계산서!E$3/재무상태표!E$7 -> 14.160524 | G10: =손익계산서!F$3/재무상태표!F$7 -> 11.241866 | I10: 2022 | J10: 28300 | K10: 29300 | L10: 30200 | M10: 30150 | N10: 29050 | O10: 25200 | P10: 25300 | Q10: 26850 | R10: 22100 | S10: 23100 | T10: 25450 | U10: 22950
B11: 매출채권회수일수 | C11: =365/C10 -> 38.647115 | D11: =365/D10 -> 45.629448 | E11: =365/E10 -> 29.586165 | F11: =365/F10 -> 25.775882 | G11: =365/G10 -> 32.46792 | I11: 2023 | J11: 24250 | K11: 22750 | L11: 23200 | M11: 22850 | N11: 22100 | O11: 24350 | P11: 24600 | Q11: 22800 | R11: 21750 | S11: 20500 | T11: 22450 | U11: 23900
A12: 시장가치 | B12: PE | C12: =J$29/((손익계산서!B$33*100000000)/J$30) -> -11.297594 | D12: =K$29/((손익계산서!C$33*100000000)/K$30) -> 17.808242 | E12: =L$29/((손익계산서!D$33*100000000)/L$30) -> 5.6411085 | F12: =M$29/((손익계산서!E$33*100000000)/M$30) -> 7.4871045 | G12: =N$29/((손익계산서!F$33*100000000)/N$30) -> 6.0077383 | I12: 2024 | J12: 22500 | K12: 23000 | L12: 21700 | M12: 20950 | N12: 20850 | O12: 23250 | P12: 21250 | Q12: 22050 | R12: 22550 | S12: 23900 | T12: 25950 | U12: 22600
B13: PS | C13: =J$29/((손익계산서!B$3*100000000)/J$30) -> 0.34145545 | D13: =K$29/((손익계산서!C$3*100000000)/K$30) -> 1.1430954 | E13: =L$29/((손익계산서!D$3*100000000)/L$30) -> 0.69212881 | F13: =M$29/((손익계산서!E$3*100000000)/M$30) -> 0.52469213 | G13: =N$29/((손익계산서!F$3*100000000)/N$30) -> 0.46454997
B14: PBR | C14: =J$29/((재무상태표!B$34*100000000)/J$30) -> 0.81043406 | D14: =K$29/((재무상태표!C$34*100000000)/K$30) -> 1.5260938 | E14: =L$29/((재무상태표!D$34*100000000)/L$30) -> 1.084735 | F14: =M$29/((재무상태표!E$34*100000000)/M$30) -> 0.88743791 | G14: =N$29/((재무상태표!F$34*100000000)/N$30) -> 0.79269884 | I14: 월별수익률 | J14: 1 | K14: 2 | L14: 3 | M14: 4 | N14: 5 | O14: 6 | P14: 7 | Q14: 8 | R14: 9 | S14: 10 | T14: 11 | U14: 12
B15: Tobin's Q | C15: =(J$31+재무상태표!B$17)/재무상태표!B$3 -> 0.97169253 | D15: =(K$31+재무상태표!C$17)/재무상태표!C$3 -> 1.1290272 | E15: =(L$31+재무상태표!D$17)/재무상태표!D$3 -> 1.0159962 | F15: =(M$31+재무상태표!E$17)/재무상태표!E$3 -> 0.9552025 | G15: =(N$31+재무상태표!F$17)/재무상태표!F$3 -> 0.94339006 | I15: 2020 | K15: =(K8-J8)/J8 -> -0.057042997 | L15: =(L8-K8)/K8 -> -0.16147982 | M15: =(M8-L8)/L8 -> 0.058882402 | N15: =(N8-M8)/M8 -> 0.045447385 | O15: =(O8-N8)/N8 -> 0.013561365 | P15: =(P8-O8)/O8 -> 0.0028989816 | Q15: =(Q8-P8)/P8 -> 0.014378891 | R15: =(R8-Q8)/Q8 -> 0.067952652 | ... U15: =(U8-T8)/T8 -> 0.066656552
B16: EV/EBITDA | C16: =(J$31+재무상태표!B$17-재무상태표!B$5)/(손익계산서!B$29+손익계산서!B$10) -> -27.240071 | D16: =(K$31+재무상태표!C$17-재무상태표!C$5)/(손익계산서!C$29+손익계산서!C$10) -> 31.503566 | E16: =(L$31+재무상태표!D$17-재무상태표!D$5)/(손익계산서!D$29+손익계산서!D$10) -> 10.708914 | F16: =(M$31+재무상태표!E$17-재무상태표!E$5)/(손익계산서!E$29+손익계산서!E$10) -> 16.957539 | G16: =(N$31+재무상태표!F$17-재무상태표!F$5)/(손익계산서!F$29+손익계산서!F$10) -> 21.896554 | I16: 2021 | J16: =(J9-U8)/U8 -> 0.36077 | K16: =(K9-J9)/J9 -> -0.019163763 | L16: =(L9-K9)/K9 -> -0.03374778 | M16: =(M9-L9)/L9 -> -0.011029412 | N16: =(N9-M9)/M9 -> 0.18773234 | O16: =(O9-N9)/N9 -> -0.014084507 | P16: =(P9-O9)/O9 -> -0.050793651 | Q16: =(Q9-P9)/P9 -> 0.046822742 | R16: =(R9-Q9)/Q9 -> 0.076677316 | ... U16: =(U9-T9)/T9 -> 0.10754717
A17: 단기지급능력 | B17: 유동비율 | C17: =재무상태표!B$4/재무상태표!B$18 -> 0.5010806 | D17: =재무상태표!C$4/재무상태표!C$18 -> 0.7863889 | E17: =재무상태표!D$4/재무상태표!D$18 -> 0.95466214 | F17: =재무상태표!E$4/재무상태표!E$18 -> 0.91342121 | G17: =재무상태표!F$4/재무상태표!F$18 -> 0.68441292 | I17: 2022 | J17: =(J10-U9)/U9 -> -0.035775128 | K17: =(K10-J10)/J10 -> 0.035335689 | L17: =(L10-K10)/K10 -> 0.030716724 | M17: =(M10-L10)/L10 -> -0.0016556291 | N17: =(N10-M10)/M10 -> -0.036484245 | O17: =(O10-N10)/N10 -> -0.13253012 | P17: =(P10-O10)/O10 -> 0.003968254 | Q17: =(Q10-P10)/P10 -> 0.061264822 | R17: =(R10-Q10)/Q10 -> -0.17690875 | ... U17: =(U10-T10)/T10 -> -0.098231827
B18: 당좌비율 | C18: =(재무상태표!B$4-재무상태표!B$8)/재무상태표!B$18 -> 0.43207573 | D18: =(재무상태표!C$4-재무상태표!C$8)/재무상태표!C$18 -> 0.71568803 | E18: =(재무상태표!D$4-재무상태표!D$8)/재무상태표!D$18 -> 0.86851952 | F18: =(재무상태표!E$4-재무상태표!E$8)/재무상태표!E$18 -> 0.82270999 | G18: =(재무상태표!F$4-재무상태표!F$8)/재무상태표!F$18 -> 0.61544108 | I18: 2023 | J18: =(J11-U10)/U10 -> 0.05664488 | K18: =(K11-J11)/J11 -> -0.06185567 | L18: =(L11-K11)/K11 -> 0.01978022 | M18: =(M11-L11)/L11 -> -0.015086207 | N18: =(N11-M11)/M11 -> -0.032822757 | O18: =(O11-N11)/N11 -> 0.10180995 | P18: =(P11-O11)/O11 -> 0.01026694 | Q18: =(Q11-P11)/P11 -> -0.073170732 | R18: =(R11-Q11)/Q11 -> -0.046052632 | ... U18: =(U11-T11)/T11 -> 0.064587973
B19: 현금비율 | C19: =재무상태표!B$5/재무상태표!B$18 -> 0.16457224 | D19: =재무상태표!C$5/재무상태표!C$18 -> 0.14036535 | E19: =재무상태표!D$5/재무상태표!D$18 -> 0.12470533 | F19: =재무상태표!E$5/재무상태표!E$18 -> 0.066184523 | G19: =재무상태표!F$5/재무상태표!F$18 -> 0.13053445 | I19: 2024 | J19: =(J12-U11)/U11 -> -0.058577406 | K19: =(K12-J12)/J12 -> 0.022222222 | L19: =(L12-K12)/K12 -> -0.056521739 | M19: =(M12-L12)/L12 -> -0.034562212 | N19: =(N12-M12)/M12 -> -0.0047732697 | O19: =(O12-N12)/N12 -> 0.11510791 | P19: =(P12-O12)/O12 -> -0.086021505 | Q19: =(Q12-P12)/P12 -> 0.037647059 | R19: =(R12-Q12)/Q12 -> 0.022675737 | ... U19: =(U12-T12)/T12 -> -0.12909441
A20: 장기지급능력 | B20: 총부채비율 | C20: =재무상태표!B$17/재무상태표!B$3 -> 0.86853052 | D20: =재무상태표!C$17/재무상태표!C$3 -> 0.7425872 | E20: =재무상태표!D$17/재무상태표!D$3 -> 0.67954493 | F20: =재무상태표!E$17/재무상태표!E$3 -> 0.67704394 | G20: =재무상태표!F$17/재무상태표!F$3 -> 0.76680047
B21: 부채비율 | C21: =재무상태표!B$17/재무상태표!B$34 -> 6.8231197 | D21: =재무상태표!C$17/재무상태표!C$34 -> 2.9325579 | E21: =재무상태표!D$17/재무상태표!D$34 -> 2.1908854 | F21: =재무상태표!E$17/재무상태표!E$34 -> 2.160043 | G21: =재무상태표!F$17/재무상태표!F$34 -> 3.4421158
B22: 장기부채비율 | C22: =재무상태표!B$25/재무상태표!B$3 -> 0.55143027 | D22: =재무상태표!C$25/재무상태표!C$3 -> 0.42596462 | E22: =재무상태표!D$25/재무상태표!D$3 -> 0.38727406 | F22: =재무상태표!E$25/재무상태표!E$3 -> 0.36742517 | G22: =재무상태표!F$25/재무상태표!F$3 -> 0.40575516
B23: 이자보상비율 | C23: =손익계산서!B$31/손익계산서!B$20 -> -1.6024848 | D23: =손익계산서!C$31/손익계산서!C$20 -> 1.4805121 | E23: =손익계산서!D$31/손익계산서!D$20 -> 4.3135126 | F23: =손익계산서!E$31/손익계산서!E$20 -> 2.1247168 | G23: =손익계산서!F$31/손익계산서!F$20 -> 2.687609
J28: 2020 | K28: 2021 | L28: 2022 | M28: 2023 | N28: 2024
I29: 연평균주가 | J29: =AVERAGE($J$8:$U$8) -> 14916.833 | K29: =AVERAGE($J$9:$U$9) -> 29633.333 | L29: =AVERAGE($J$10:$U$10) -> 26495.833 | M29: =AVERAGE($J$11:$U$11) -> 22958.333 | N29: =AVERAGE($J$12:$U$12) -> 22545.833
I30: 주식수 | J30: 174209713 | K30: 347820825 | L30: 368220661 | M30: 368220661 | N30: 368220661
I31: 시가총액(억원) | J31: =J29*J30/100000000 -> 25986.573 | K31: =K29*K30/100000000 -> 103070.9 | L31: =L29*L30/100000000 -> 97563.133 | M31: =M29*M30/100000000 -> 84537.327 | N31: =N29*N30/100000000 -> 83018.417
B34: 2020 KE | C34: 2020 OZ | D34: 2020 산업평균 | E34: 2021 KE | F34: 2021 OZ | G34: 2021 산업평균 | H34: 2022 KE | I34: 2022 OZ | J34: 2022 산업평균 | K34: 2023 KE | L34: 2023 OZ | M34: 2023 산업평균
A35: 유동비율 | B35: 50.1 | C35: 45.5 | D35: 54.9 | E35: 70.3 | F35: 49 | G35: 73.9 | H35: 88.4 | I35: 47.6 | J35: 79.7 | K35: 91 | L35: 39.3 | M35: 78.3
A36: 당좌비율 | B36: 43.6 | C36: 35.3 | D36: 49.6 | E36: 65.8 | F36: 41.2 | G36: 68.6 | H36: 78.9 | I36: 38.9 | J36: 74.1 | K36: 82.3 | L36: 31.2 | M36: 72.1
A37: 부채비율 | B37: 660.3 | C37: 1174.2 | D37: 535 | E37: 295.8 | F37: 2411 | G37: 349.7 | H37: 235.5 | I37: 1780.3 | J37: 282.2 | K37: 210.3 | L37: 1161 | M37: 260.6
A38: 차입금의존도 | B38: 29.7 | C38: 36.6 | D38: 37.4 | E38: 21.5 | F38: 26.1 | G38: 22.9 | H38: 12.1 | I38: 26.5 | J38: 20.3 | K38: 9.9 | L38: 27.2 | M38: 18
A39: 총자산회전율 | B39: 0.36 | C39: 0.31 | D39: 0.31 | E39: 0.41 | F39: 0.36 | G39: 0.36 | H39: 0.58 | I39: 0.52 | J39: 0.52 | K39: 0.72 | L39: 0.6 | M39: 0.61
A40: ROE | B40: -36.4 | C40: -36.7 | D40: -21.7 | E40: 15.5 | F40: -10.6 | G40: -10.6 | H40: 15.4 | I40: 24.3 | J40: 24.3 | K40: 10.9 | L40: 17.7 | M40: 17.7
A41: ROA | B41: -3.9 | C41: -3.3 | D41: -3.3 | E41: 3.6 | F41: -2 | G41: -2 | H41: 6.2 | I41: 5.9 | J41: 5.9 | K41: 4.4 | L41: 4.8 | M41: 4.8
A42: 영업이익률 | B42: 1.4 | C42: -7 | D42: -5.8 | E42: 15.7 | F42: 2.1 | G42: 3.6 | H42: 20.1 | I42: 9.6 | J42: 15.3 | K42: 13.4 | L42: 8.1 | M42: 11.9
B44: Altman Z Score
B45: X1 | C45: X2 | D45: X3 | E45: X4 | F45: X5 | G45: Altman Z Score
A46: 2020 | B46: =(재무상태표!B$4-재무상태표!B$18)/재무상태표!B$3 -> -0.15820747 | C46: =재무상태표!B$38/재무상태표!B$3 -> -0.020742428 | D46: =손익계산서!B$29/재무상태표!B$3 -> -0.03714549 | E46: =J$31/재무상태표!B$17 -> 0.11877764 | F46: =손익계산서!B$3/재무상태표!B$3 -> 0.30212435 | G46: =(1.2*$B46)+(1.4*$C46)+(3.3*$D46)+(0.6*$E46)+$F46 -> 0.03192246
A47: 2021 | B47: =(재무상태표!C$4-재무상태표!C$18)/재무상태표!C$3 -> -0.0676341 | C47: =재무상태표!C$38/재무상태표!C$3 -> 0.0041270702 | D47: =손익계산서!C$29/재무상태표!C$3 -> 0.031610568 | E47: =K$31/재무상태표!C$17 -> 0.5203968 | F47: =손익계산서!C$3/재무상태표!C$3 -> 0.33806454 | G47: =(1.2*$B47)+(1.4*$C47)+(3.3*$D47)+(0.6*$E47)+$F47 -> 0.67923447
...

Sheet 추정현금흐름표
B1: (단위: 억원)
B2: 2020 | C2: 2021 | D2: 2022 | E2: 2023 | F2: 2024 | J2: 2020 | K2: 2021 | L2: 2022 | M2: 2023 | N2: 2024 | O2: 2025E | P2: 2026E | Q2: 2027E
A3: 매출액 | B3: =손익계산서!$B$3 -> 76105.309 | C3: =손익계산서!$C$3 -> 90168.246 | D3: =손익계산서!$D$3 -> 140960.95 | E3: =손익계산서!$E$3 -> 161117.96 | F3: =손익계산서!$F$3 -> 178707.18 | I3: 매출액 | J3: =손익계산서!$B$3 -> 76105.309 | K3: =손익계산서!$C$3 -> 90168.246 | L3: =손익계산서!$D$3 -> 140960.95 | M3: =손익계산서!$E$3 -> 161117.96 | N3: =손익계산서!$F$3 -> 178707.18 | O3: =N3*(1+$G$15) -> 223395.59 | P3: =O3*(1+$G$15) -> 279259.01 | Q3: =P3*(1+$G$15) -> 349091.9
A4: 매출원가 | B4: =손익계산서!$B$6 -> 68501.042 | C4: =손익계산서!$C$6 -> 69120.471 | D4: =손익계산서!$D$6 -> 102454.4 | E4: =손익계산서!$E$6 -> 128503.02 | F4: =손익계산서!$F$6 -> 141125.5 | I4: 매출원가 | J4: =손익계산서!$B$6 -> 68501.042 | K4: =손익계산서!$C$6 -> 69120.471 | L4: =손익계산서!$D$6 -> 102454.4 | M4: =손익계산서!$E$6 -> 128503.02 | N4: =손익계산서!$F$6 -> 141125.5 | O4: =O3*$G$16 -> 177856.68 | P4: =P3*$G$16 -> 222332.41 | Q4: =Q3*$G$16 -> 277929.96
A5: 매출총이익 | B5: =손익계산서!$B$7 -> 7604.2671 | C5: =손익계산서!$C$7 -> 21047.776 | D5: =손익계산서!$D$7 -> 38506.544 | E5: =손익계산서!$E$7 -> 32614.942 | F5: =손익계산서!$F$7 -> 37581.684 | I5: 매출총이익 | J5: =손익계산서!$B$7 -> 7604.2671 | K5: =손익계산서!$C$7 -> 21047.776 | L5: =손익계산서!$D$7 -> 38506.544 | M5: =손익계산서!$E$7 -> 32614.942 | N5: =손익계산서!$F$7 -> 37581.684 | O5: =O3-O4 -> 45538.912 | P5: =P3-P4 -> 56926.598 | Q5: =Q3-Q4 -> 71161.947
A6: 판매비와관리비 | B6: =손익계산서!$B$8 -> 6531.0268 | C6: =손익계산서!$C$8 -> 6868.0894 | D6: =손익계산서!$D$8 -> 10200.676 | E6: =손익계산서!$E$8 -> 14714.05 | F6: =손익계산서!$F$8 -> 16479.683 | I6: 판매비와관리비 | J6: =손익계산서!$B$8 -> 6531.0268 | K6: =손익계산서!$C$8 -> 6868.0894 | L6: =손익계산서!$D$8 -> 10200.676 | M6: =손익계산서!$E$8 -> 14714.05 | N6: =손익계산서!$F$8 -> 16479.683 | O6: =O3*$G$17 -> 18671.022 | P6: =P3*$G$17 -> 23339.99 | Q6: =Q3*$G$17 -> 29176.505
A7: 영업이익 | B7: =손익계산서!$B$15 -> 1073.2404 | C7: =손익계산서!$C$15 -> 14179.686 | D7: =손익계산서!$D$15 -> 28305.868 | E7: =손익계산서!$E$15 -> 17900.892 | F7: =손익계산서!$F$15 -> 21102.001 | I7: 영업이익 | J7: =손익계산서!$B$15 -> 1073.2404 | K7: =손익계산서!$C$15 -> 14179.686 | L7: =손익계산서!$D$15 -> 28305.868 | M7: =손익계산서!$E$15 -> 17900.892 | N7: =손익계산서!$F$15 -> 21102.001 | O7: =O5-O6 -> 26867.89 | P7: =P5-P6 -> 33586.608 | Q7: =Q5-Q6 -> 41985.442
A8: 영업외수익 | B8: =손익계산서!$B$16+손익계산서!$B$22 -> 9903.819 | C8: =손익계산서!$C$16+손익계산서!$C$22 -> 9383.1366 | D8: =손익계산서!$D$16+손익계산서!$D$22 -> 13525.602 | E8: =손익계산서!$E$16+손익계산서!$E$22 -> 10104.378 | F8: =손익계산서!$F$16+손익계산서!$F$22 -> 15635.404 | I8: 영업외수익 | J8: =손익계산서!$B$16+손익계산서!$B$22 -> 9903.819 | K8: =손익계산서!$C$16+손익계산서!$C$22 -> 9383.1366 | L8: =손익계산서!$D$16+손익계산서!$D$22 -> 13525.602 | M8: =손익계산서!$E$16+손익계산서!$E$22 -> 10104.378 | N8: =손익계산서!$F$16+손익계산서!$F$22 -> 15635.404 | O8: - | P8: - | Q8: -
A9: 영업외비용 | B9: =손익계산서!$B$19+손익계산서!$B$23 -> 20343.299 | C9: =손익계산서!$C$19+손익계산서!$C$23 -> 15132.024 | D9: =손익계산서!$D$19+손익계산서!$D$23 -> 16208.073 | E9: =손익계산서!$E$19+손익계산서!$E$23 -> 12248.567 | F9: =손익계산서!$F$19+손익계산서!$F$23 -> 18376.009 | I9: 영업외비용 | J9: =손익계산서!$B$19+손익계산서!$B$23 -> 20343.299 | K9: =손익계산서!$C$19+손익계산서!$C$23 -> 15132.024 | L9: =손익계산서!$D$19+손익계산서!$D$23 -> 16208.073 | M9: =손익계산서!$E$19+손익계산서!$E$23 -> 12248.567 | N9: =손익계산서!$F$19+손익계산서!$F$23 -> 18376.009 | O9: - | P9: - | Q9: -
A10: 법인세차감전순이익 | B10: =손익계산서!$B$29 -> -9356.9716 | C10: =손익계산서!$C$29 -> 8431.1402 | D10: =손익계산서!$D$29 -> 25621.35 | E10: =손익계산서!$E$29 -> 15756.904 | F10: =손익계산서!$F$29 -> 18361.756 | I10: 법인세차감전순이익 | J10: =손익계산서!$B$29 -> -9356.9716 | K10: =손익계산서!$C$29 -> 8431.1402 | L10: =손익계산서!$D$29 -> 25621.35 | M10: =손익계산서!$E$29 -> 15756.904 | N10: =손익계산서!$F$29 -> 18361.756 | O10: =O7 -> 26867.89 | P10: =P7 -> 33586.608 | Q10: =Q7 -> 41985.442
A11: 법인세 등 | B11: =손익계산서!$B$30 -> -1122.4026 | C11: =손익계산서!$C$30 -> 2643.3199 | D11: =손익계산서!$D$30 -> 8326.3215 | E11: =손익계산서!$E$30 -> 4465.8463 | F11: =손익계산서!$F$30 -> 4543.1751 | I11: 법인세 등 | J11: =손익계산서!$B$30 -> -1122.4026 | K11: =손익계산서!$C$30 -> 2643.3199 | L11: =손익계산서!$D$30 -> 8326.3215 | M11: =손익계산서!$E$30 -> 4465.8463 | N11: =손익계산서!$F$30 -> 4543.1751 | O11: =O10*$G$23 -> 6928.1311 | P11: =P10*$G$23 -> 8660.614 | Q11: =Q10*$G$23 -> 10826.33
A12: 당기순이익 | B12: =손익계산서!$B$33 -> -2300.1863 | C12: =손익계산서!$C$33 -> 5787.8203 | D12: =손익계산서!$D$33 -> 17295.029 | E12: =손익계산서!$E$33 -> 11291.057 | F12: =손익계산서!$F$33 -> 13818.581 | I12: 당기순이익 | J12: =손익계산서!$B$33 -> -2300.1863 | K12: =손익계산서!$C$33 -> 5787.8203 | L12: =손익계산서!$D$33 -> 17295.029 | M12: =손익계산서!$E$33 -> 11291.057 | N12: =손익계산서!$F$33 -> 13818.581 | O12: =O10-O11 -> 19939.759 | P12: =P10-P11 -> 24925.994 | Q12: =Q10-Q11 -> 31159.112
I13: 배당금 | J13: =-현금흐름표!$B$95 -> 610 | K13: =-현금흐름표!$C$95 -> 182 | L13: =-현금흐름표!$D$95 -> 46 | M13: =-현금흐름표!$E$95 -> 2821 | N13: =-현금흐름표!$F$95 -> 2782 | O13: =O12*$G$24 -> 2419.0514 | P13: =P12*$G$24 -> 3023.9714 | Q13: =Q12*$G$24 -> 3780.1607
G14: 평균
A15: 매출액증가율 | C15: =(C3-B3)/B3 -> 0.1847826 | D15: =(D3-C3)/C3 -> 0.5633103 | E15: =(E3-D3)/D3 -> 0.14299714 | F15: =(F3-E3)/E3 -> 0.10916985 | G15: =AVERAGE(C15:F15) -> 0.25006497 | J15: 2020 | K15: 2021 | L15: 2022 | M15: 2023 | N15: 2024 | O15: 평균
A16: 매출원가율 | B16: =B4/B3 -> 0.9000823 | C16: =C4/C3 -> 0.7665722 | D16: =D4/D3 -> 0.72682829 | E16: =E4/E3 -> 0.79757103 | F16: =F4/F3 -> 0.78970245 | G16: =AVERAGE(B16:F16) -> 0.79615125 | I16: 매출채권회전율 | J16: =재무비율분석!$C$10 -> 9.4444307 | K16: =재무비율분석!$D$10 -> 7.9992202 | L16: =재무비율분석!$E$10 -> 12.336847 | M16: =재무비율분석!$F$10 -> 14.160524 | N16: =재무비율분석!$G$10 -> 11.241866 | O16: =AVERAGE(J16:N16) -> 11.036578
A17: 판관비/매출액 | B17: =B6/B3 -> 0.085815653 | C17: =C6/C3 -> 0.076169713 | D17: =D6/D3 -> 0.072365265 | E17: =E6/E3 -> 0.091324706 | F17: =F6/F3 -> 0.092216119 | G17: =AVERAGE(B17:F17) -> 0.083578291 | I17: 재고자산회전율 | J17: =재무비율분석!$C$8 -> 12.427724 | K17: =재무비율분석!$D$8 -> 11.576734 | L17: =재무비율분석!$E$8 -> 14.033418 | M17: =재무비율분석!$F$8 -> 15.05459 | N17: =재무비율분석!$G$8 -> 12.054872 | O17: =AVERAGE(J17:N17) -> 13.029468
A18: 영업이익/매출액 | B18: =B7/B3 -> 0.014102043 | C18: =C7/C3 -> 0.15725809 | D18: =D7/D3 -> 0.20080645 | E18: =E7/E3 -> 0.11110426 | F18: =F7/F3 -> 0.11808143 | G18: =AVERAGE(B18:F18) -> 0.12027046 | I18: 매입채무최전율 | J18: =손익계산서!$B$3/재무상태표!$B$19 -> 9.138575 | K18: =손익계산서!$C$3/재무상태표!$C$19 -> 9.5005996 | L18: =손익계산서!$D$3/재무상태표!$D$19 -> 10.116891 | M18: =손익계산서!$E$3/재무상태표!$E$19 -> 8.8813605 | N18: =손익계산서!$F$3/재무상태표!$F$19 -> 5.1579839 | O18: =AVERAGE(J18:N18) -> 8.5590821
A19: 당기순이익/매출액 | B19: =B12/B3 -> -0.03022373 | C19: =C12/C3 -> 0.064189119 | D19: =D12/D3 -> 0.12269376 | E19: =E12/E3 -> 0.070079445 | F19: =F12/F3 -> 0.077325267 | G19: =AVERAGE(B19:F19) -> 0.060812772 | I19: 기타유동자산회전율 | J19: =손익계산서!$B$3/재무상태표!$B$9 -> 11.129762 | K19: =손익계산서!$C$3/재무상태표!$C$9 -> 13.755644 | L19: =손익계산서!$D$3/재무상태표!$D$9 -> 80.641275 | M19: =손익계산서!$E$3/재무상태표!$E$9 -> 44.057413 | N19: =손익계산서!$F$3/재무상태표!$F$9 -> 9.1560193 | O19: =AVERAGE(J19:N19) -> 31.748023
I20: 기타유동부채회전율 | J20: =손익계산서!$B$3/재무상태표!$B$24 -> 6.8967204 | K20: =손익계산서!$C$3/재무상태표!$C$24 -> 5.219278 | L20: =손익계산서!$D$3/재무상태표!$D$24 -> 5.8846518 | M20: =손익계산서!$E$3/재무상태표!$E$24 -> 4.6114073 | N20: =손익계산서!$F$3/재무상태표!$F$24 -> 3.6292355 | O20: =AVERAGE(J20:N20) -> 5.2482586
A21: 감가상각비 | B21: =손익계산서!$B$10 -> 853.89976 | C21: =손익계산서!$C$10 -> 751.28988 | D21: =손익계산서!$D$10 -> 902.95903 | E21: =손익계산서!$E$10 -> 995.24 | F21: =손익계산서!$F$10 -> 881.04 | G21: =AVERAGE(B21:F21) -> 876.88573
A22: 배당금의 지급 | B22: =-현금흐름표!$B$95 -> 610 | C22: =-현금흐름표!$C$95 -> 182 | D22: =-현금흐름표!$D$95 -> 46 | E22: =-현금흐름표!$E$95 -> 2821 | F22: =-현금흐름표!$F$95 -> 2782
A23: 법인세율(법인세/법인세차감전순이익) | B23: =B11/B10 -> 0.11995362 | C23: =C11/C10 -> 0.31351867 | D23: =D11/D10 -> 0.32497591 | E23: =E11/E10 -> 0.28342156 | F23: =F11/F10 -> 0.24742596 | G23: =AVERAGE(B23:F23) -> 0.25785914
A24: 배당성향(배당금/당기순이익) | B24: =B22/B12 -> -0.2651959 | C24: =C22/C12 -> 0.031445344 | D24: =D22/D12 -> 0.0026597239 | E24: =E22/E12 -> 0.24984374 | F24: =F22/F12 -> 0.20132314 | G24: =AVERAGE(C24:F24) -> 0.12131799
B26: 금액 (단위: 억원)
B27: 2020 | C27: 2021 | D27: 2022 | E27: 2023 | F27: 2024 | G27: 2025E | H27: 2026E | I27: 2027E
A28: 자산(*) | B28: 251900.61 | C28: 266719.03 | D28: 289977.01 | E28: 303917.76 | F28: 470120.66
A29: 유동자산(*) | B29: 40025.19 | C29: 66409.968 | D29: 80909.367 | E29: 85951.696 | F29: 116168.73
A30: 현금및현금성자산(*) | B30: 13145.66 | C30: 11853.751 | D30: 10569.005 | E30: 6227.8738 | F30: 22156.246
A31: 유동금융자산(*) | B31: 6470.9663 | C31: 30758.165 | D31: 49865.23 | E31: 56152.599 | F31: 46890.718
A32: 매출채권및기타유동채권(*) | B32: 8058.221 | C32: 11272.13 | D32: 11426.011 | E32: 11377.966 | F32: 15896.577 | G32: =O3*$O$16 -> 2465522.8 | H32: =P3*$O$16 -> 3082063.7 | I32: =Q3*$O$16 -> 3852779.9
A33: 재고자산(*) | B33: 5511.9538 | C33: 5970.6364 | D33: 7300.745 | E33: 8535.8031 | F33: 11706.926 | G33: =O3*$O$17 -> 2910725.7 | H33: =P3*$O$17 -> 3638596.2 | I33: =Q3*$O$17 -> 4548481.7
A34: 기타유동자산(*) | B34: 6838 | C34: 6555 | D34: 1748 | E34: 3657 | F34: 19518 | G34: =O3*$O$19 -> 7092368.3 | H34: =P3*$O$19 -> 8865921.2 | I34: =Q3*$O$19 -> 11082978
A35: 비유동자산(*) | B35: 211875.42 | C35: 200309.06 | D35: 209067.64 | E35: 217966.06 | F35: 353951.93
A36: 기타비유동자산(*) | B36: 6850.7951 | C36: 10127.43 | D36: 11278.324 | E36: 9651.1415 | F36: 5401.6574
A37: 투자부동산(*) | B37: 2565.7746 | C37: 2625.0993 | D37: 2687.3101 | E37: 2607.491 | F37: 2778.6307
A38: 유형자산(*) | B38: 184821.4 | C38: 169140.84 | D38: 170790.86 | E38: 181748.87 | F38: 283744.91
A39: 무형자산(*) | B39: 2681.4515 | C39: 2759.8427 | D39: 8737.5452 | E39: 8241.8568 | F39: 30774.07
A40: 기타비유동자산(*) | B40: 14892 | C40: 15594 | D40: 15574 | E40: 15717 | F40: 29707
A41: 부채(*) | B41: 218783.37 | C41: 198062.14 | D41: 197052.41 | E41: 205765.68 | F41: 360488.74
...
